Workbook

Sheet Info
A1: Project Workbook Information
A3: The project workbook allows project managers, team members, sponsors, and stakeholders to easily track and monitor project activities. Any of these worksheets can easily be broken out into separate documents.
A5: Suggested Sheets for All Projects
A6: Data | B6: Filling out the Data sheet completes the header portion of all remaining sheets in the project workbook.
A7: Minicharter | B7: The Project Minicharter sheet can be used as a charter for small projects or a summarization of a full charter for larger projects.
A8: Stoplight | B8: The Stoplight Report sheet contains a status report that can be used to keep sponsors, team members, and stakeholders informed of project progress.
A9: Budget | B9: The Budget sheet allows you to track original budget, expenditures to date, and any cost variance.
A10: CBA | B10: The Cost/Benefit Analysis sheet allows you to review the proposed project and potential alternatives and make a project selection based on a greater ROI (return on investment).
A11: Risks | B11: The Risk Management Matrix sheet allows you to identify, qualify, quantify, and prioritize risks (events that might happen; the uncertainty of a project), create mitigation and contingency plans, and assign risks owners.
A12: Issues | B12: The Issues Log sheet allows you to identify and monitor project issues (unplanned events that have happened).
A13: Action | B13: The Action Items sheet allows you to track and monitor action items assigned to team members. Action items are tasks that must be done but are too insignificant from a time perspective to track in your project schedule.
A14: Miles | B14: The Deliverable Milestones sheet allows you to identify major deliverable milestones and the due dates, objectives, assumptions, and constraints relevant to that deliverable milestone.
A15: WBS | B15: The Work Breakdown Structure sheet includes the activities that must be completed during a project, the effort required, all relevant dates, and the resources assigned to do the work.
A16: Roster | B16: The Roster sheet provides contact information for all those involved on the project.
A17: R&R | B17: The Roles and Responsibilities sheet shows the primary role of team members, any deliverables in which they are involved, and the percentage of time they are expected to work on the project.
... A35: Portfolio Review | B35: The Portfolio Review sheet identifies the CPI and SPI, status, and recommendations for each project in the portfolio.
B37: © Global Knowledge Training LLC

Sheet Data
A1: Project | B1: Personal Cybersecurity Risk Scanner
A2: Project # | B2: #12
A3: Project manager | B3: Mohammedreda El aroui
A4: Sponsor | B4: Mohamed AAZI
A5: Project artifacts | B5: https://github.com/project12/personal-cybersecurity-risk-scanner
A6: Last updated | B6: 2/4/2026
B8: © Global Knowledge Training LLC

Sheet Minicharter
A1: Project Minicharter
A2: Project | B2: =Data!B1 | C2: Project # | D2: =Data!B2
A3: Project manager | B3: =Data!B3 | C3: Sponsor | D3: =Data!B4
A4: Project artifacts | B4: =Data!B5 | C4: Updated | D4: =Data!B6
A5: Background | B5: Individuals and small organizations lack visibility into their cybersecurity posture. Many users unknowingly expose themselves through weak passwords, open ports, outdated software, or insecure configurations.
A6: Business need and business benefits | B6: Increase cybersecurity awareness for non-experts; Provide accessible and affordable risk assessment; Reduce exposure to common attacks; Enable proactive security practices; Potential SaaS tool for individuals or SMEs.
A7: Objectives | B7: 1. Develop a personal cybersecurity risk scanner tool. 2. Implement automated scanning of user environment. 3. Generate actionable risk scores and recommendations. 4. Deliver a simple dashboard/report for end-users.
A8: Scope | B8: In Scope | C8: Out of Scope
B9: Port scanning, password strength evaluation, vulnerability/config checking, risk scoring, dashboard
B10: Enterprise security auditing, penetration testing, hardware security assessments, cloud deployment (v1)
A12: Deliverables | B12: Cybersecurity Risk Scanner (CLI/Desktop app) | C12: Due Date
B13: Risk Score Dashboard and Report Generator
B14: User Documentation and Deployment Guide
A16: Flexibility matrix | B16: Scope
B17: Schedule
B18: Cost
A19: Key considerations | B19: Assumptions & Constraints | C19: Risks
C20: Technical | D20: Inaccurate vulnerability detection due to platform differences
C21: Scope | D21: Scope creep from expanding feature requests
C22: Legal | D22: Data privacy non-compliance (GDPR)
C23: Resource | D23: Team member unavailability
C24: Financial | D24: Budget overrun
A28: Success criteria | B28: Scanner accurately detects at least 90% of common vulnerabilities in test environment
B29: Risk score is generated within 2 minutes of scan completion
B30: Dashboard is rated as easy to use by at least 80% of beta testers
B31: Zero data privacy breaches during testing and deployment phases
B32: Project delivered on time and within the approved budget
A33: Signatures
A34: Sponsor
B35: Signature
B37: Printed name
B39: Date
A41: Project manager
B43: Signature
B45: Printed name
B47: Date
D49: © Global Knowledge Training LLC

Sheet Stoplight
A1: Stoplight Report
A2: Project | B2: =Data!B1 | G2: Project # | H2: =Data!B2
A3: Project manager | B3: =Data!B3 | G3: Sponsor | H3: =Data!B4
A4: Project artifacts | B4: =Data!B5 | G4: Updated | H4: =Data!B6
B6: Deliverables
B7: 1 | C7: 2 | D7: 3 | E7: 4 | F7: 5 | G7: 6 | H7: 7 | I7: 8 | J7: 9 | K7: 10
A8: Schedule
A9: Scope
A10: Cost
A11: Risk
A12: Issues
A13: Planned completion
A14: Est. completion
A16: Management Alert
A17: ID | B17: Situation Requiring Management Attention | F17: Action Plan | J17: Owner
A22: Accomplishments During Reporting Period
A23: ID | B23: Description of Accomplishment | E23: Planned Completion | F23: Date Completed | G23: Owner | I23: Comments
A28: Deliverables | B28: Title/Description | G28: Title/Description
A29: 1 | F29: 6
A30: 2 | F30: 7
A31: 3 | F31: 8
A32: 4 | F32: 9
A33: 5 | F33: 10
K35: © Global Knowledge Training LLC

Sheet Budget
A1: Budget
A2: Project | B2: =Data!B1 | C2: Project # | D2: =Data!B2
A3: Project manager | B3: =Data!B3 | C3: Sponsor | D3: =Data!B4
A4: Project artifacts | B4: =Data!B5 | C4: Updated | D4: =Data!B6
A6: Budget Status
A7: Approved Budget | B7: Planned Expenditures to Date | C7: Actual Expenditures to Date | D7: Variance
A8: 0 | B8: 0 | C8: 0 | D8: =SUM(B8-C8)
B9: Planned Remaining Budget | C9: Actual Remaining Budget | D9: Variance
B10: =SUM(A8-B8) | C10: =SUM(A8-C8) | D10: =SUM(B10-C10)
A11: Additional $ needed
A13: Budget Details
A14: Internal Expenses
A15: Salaries | B15: Hourly Rate | C15: # Hours | D15: Total Cost
A16: Type of resource | B16: 0 | C16: 0 | D16: =SUM(B16*C16)
A17: Type of resource | B17: 0 | C17: 0 | D17: =SUM(B17*C17)
A18: Type of resource | B18: 0 | C18: 0 | D18: =SUM(B18*C18)
A19: Type of resource | B19: 0 | C19: 0 | D19: =SUM(B19*C19)
A20: Type of resource | B20: 0 | C20: 0 | D20: =SUM(B20*C20)
A21: Type of resource | B21: 0 | C21: 0 | D21: =SUM(B21*C21)
A22: Other Internal Expenses | D22: Total Cost
A23: Type of expense | D23: 0
A24: Type of expense | D24: 0
A25: Type of expense | D25: 0
A26: Total Internal Expenses | E26: =SUM(D15:D25)
A27: External Expenses
A28: Consulting Costs | D28: Total Cost
A29: Type of consulting | D29: 0
A30: Type of consulting | D30: 0
A31: Type of consulting | D31: 0
A32: Capital Expenditures | D32: Total Cost
A33: Type of expense | D33: 0
A34: Type of expense | D34: 0
A35: Type of expense | D35: 0
A36: Total External Expenses | E36: =SUM(D28:D35)
A37: Total Budget | E37: =SUM(E15:E36)
E39: © Global Knowledge Training LLC

Sheet CBA
A1: Cost/Benefit Analysis
A2: Project | B2: =Data!B1 | E2: Project # | F2: =Data!B2
A3: Project manager | B3: =Data!B3 | E3: Sponsor | F3: =Data!B4
A4: Project artifacts | B4: =Data!B5 | E4: Updated | F4: =Data!B6
A6: Project Development and Maintenance Costs
A7: Description | B7: FY01 | C7: FY02 | D7: FY03 | E7: FY04 | F7: FY05 | G7: Total
A8: Cost of Project Development
A9: Salaries
A10: Other internal expenses
A11: Consulting costs
A12: Capital expenditures
A13: Total project costs | B13: =SUM(B8:B12) | C13: =SUM(C8:C12) | D13: =SUM(D8:D12) | E13: =SUM(E8:E12) | F13: =SUM(F8:F12) | G13: =SUM(G8:G12)
A14: Cost of Support
A15: Operational costs
A16: Nonrecurring costs
A17: Recurring costs
A18: Total ongoing support costs | B18: =SUM(B15:B17) | C18: =SUM(C15:C17) | D18: =SUM(D15:D17) | E18: =SUM(E15:E17) | F18: =SUM(F15:F17) | G18: =SUM(G15:G17)
A20: Benefits/Savings
A21: Current Process | B21: FY01 | C21: FY02 | D21: FY03 | E21: FY04 | F21: FY05 | G21: Total
A22: Total annual price
A23: New Process
A24: Total annual price
A25: Annual savings | B25: =SUM(B22-B24) | C25: =SUM(C22-C24) | D25: =SUM(D22-D24) | E25: =SUM(E22-E24) | F25: =SUM(F22-F24) | G25: =SUM(G22-G24)
A26: Cumulative savings | B26: =B25 | C26: =B26+C25 | D26: =C26+D25 | E26: =D26+E25 | F26: =E26+F25 | G26: =F26+G25
A27: Cumulative costs | B27: =B18 | C27: =C18 | D27: =D18 | E27: =E18 | F27: =F18 | G27: =G18
A28: Cumulative total net savings | B28: =B26-B27 | C28: =C26-C27 | D28: =D26-D27 | E28: =E26-E27 | F28: =F26-F27 | G28: =G26-G27
A30: Future Value
A31: Present Value | B31: Interest Rate | D31: # Periods | F31: Future Value
F32: =SUM((A32)*((1+B32)^D32))
A34: Present Value
A35: Future Value | B35: Interest Rate | D35: # Periods | F35: Present Value
A36: =F32 | F36: =SUM((A36)/((1+B36)^D36))
A38: Net Present Value
A39: Period | B39: Cash Flow | F39: Present Value
A40: 1
A41: 2
A42: 3
A43: 4
A44: 5
A45: Totals | B45: =SUM(B40:E44) | F45: 0
...

Sheet Risks
A1: Risk Management Matrix (Risk Register)
A2: Project | D2: Personal Cybersecurity Risk Scanner | J2: Project # | K2: #12
A3: Project manager | D3: Mohammedreda El aroui | J3: Sponsor | K3: Mohamed AAZI
A4: Project artifacts | D4: =Data!B5 | J4: Updated | K4: 2/4/2026
A6: ID | B6: Risk Description | C6: Probability | D6: Impact | E6: Detectability | F6: Importance | G6: Category | H6: Trigger Event/Indicator | I6: Risk Response and Description | J6: Contingency Plan | K6: Owner | L6: Status | M6: Date Entered | N6: Date to Review
A7: 1 | B7: Scope creep due to expanding feature requests | C7: 3 | D7: 4 | E7: 2 | F7: 12 | G7: Scope | H7: Stakeholder requests additional scan modules mid-project | I7: Mitigate: Apply formal change control process; evaluate all new requests before approval | J7: Freeze scope; defer new features to next release | K7: Project Manager | L7: Open | M7: 2/4/2026 | N7: 2026-05-01
A8: 2 | B8: Data privacy breach during system scanning | C8: 2 | D8: 5 | E8: 3 | F8: 10 | G8: Technical/Legal | H8: Scanner accesses sensitive user data and logs are exposed | I8: Mitigate: Encrypt all scan data; implement strict data handling policies | J8: Halt scanning; notify affected users; apply data breach response plan | K8: Security Lead | L8: Open | M8: 2/4/2026 | N8: 2026-05-01
A9: 3 | B9: Inaccurate vulnerability detection (false positives/negatives) | C9: 3 | D9: 4 | E9: 3 | F9: 12 | G9: Technical/Quality | H9: QA testing reveals scan results don't match real vulnerabilities | I9: Mitigate: Extensive testing against known vulnerability datasets | J9: Use third-party validation tools; recalibrate detection thresholds | K9: Dev Lead | L9: Open | M9: 2/4/2026 | N9: 2026-05-01
A10: 4 | B10: Team member unavailability | C10: 3 | D10: 3 | E10: 2 | F10: 9 | G10: Resource | H10: Key developer leaves or is unavailable for an extended period | I10: Mitigate: Cross-train team members; maintain up-to-date documentation | J10: Redistribute tasks; bring in external consultant if needed | K10: Project Manager | L10: Open | M10: 2/4/2026 | N10: 2026-05-01
A11: 5 | B11: Technology compatibility issues across OS platforms | C11: 3 | D11: 3 | E11: 2 | F11: 9 | G11: Technical | H11: Scanner fails on certain OS versions (Windows, Linux, macOS) | I11: Mitigate: Early cross-platform testing in development phase | J11: Limit scope to supported platforms; publish compatibility requirements | K11: Dev Lead | L11: Open | M11: 2/4/2026 | N11: 2026-05-01
A12: 6 | B12: Budget overrun | C12: 2 | D12: 4 | E12: 2 | F12: 8 | G12: Financial | H12: Actual development costs exceed approved budget | I12: Mitigate: Track expenditures weekly; use open-source tools | J12: Request additional funding from sponsor; reduce non-critical features | K12: Project Manager | L12: Open | M12: 2/4/2026 | N12: 2026-05-01
A13: 7 | B13: Schedule delay | C13: 3 | D13: 3 | E13: 2 | F13: 9 | G13: Schedule | H13: Sprint deliverables not completed on time due to technical complexity | I13: Mitigate: Use Agile sprints with clear criteria; weekly status reviews | J13: Re-baseline schedule; reallocate resources to critical path tasks | K13: Project Manager | L13: Open | M13: 2/4/2026 | N13: 2026-05-01
A14: 8 | B14: Legal/Regulatory non-compliance | C14: 2 | D14: 5 | E14: 3 | F14: 10 | G14: Legal/Compliance | H14: Tool found to violate GDPR or local privacy laws during legal review | I14: Mitigate: Conduct legal review early; consult data privacy expert | J14: Suspend distribution; engage legal counsel; adjust data handling | K14: Sponsor | L14: Open | M14: 2/4/2026 | N14: 2026-05-01
A15: 9 | B15: Low user adoption due to poor UX | C15: 3 | D15: 3 | E15: 3 | F15: 9 | G15: Business | H15: Beta testers find the dashboard confusing or not user-friendly | I15: Mitigate: Conduct UX testing with non-technical users during development | J15: Redesign UI based on feedback; provide user guides | K15: Product Owner | L15: Open | M15: 2/4/2026 | N15: 2026-05-01
A16: 10 | B16: Third-party library vulnerabilities | C16: 2 | D16: 4 | E16: 3 | F16: 8 | G16: Technical/Security | H16: A dependency used in scanner has a known CVE | I16: Mitigate: Use dependency scanning tools (e.g., Dependabot) in CI/CD | J16: Patch or replace affected library immediately; re-test all modules | K16: Dev Lead | L16: Open | M16: 2/4/2026 | N16: 2026-05-01
A17: 11 | F17: =C17*(D17)*E17
A18: 12 | F18: =C18*(D18)*E18
A19: 13 | F19: =C19*(D19)*E19
A20: 14 | F20: =C20*(D20)*E20
A21: 15 | F21: =C21*(D21)*E21
N23: © Global Knowledge Training LLC

Sheet Issues
A1: Issues Log
A2: Project | C2: =Data!B1 | E2: Project # | F2: =Data!B2
A3: Project manager | C3: =Data!B3 | E3: Sponsor | F3: =Data!B4
A4: Project artifacts | C4: =Data!B5 | E4: Updated | F4: =Data!B6
A6: ID | B6: Issue Description | C6: Project Impact | D6: Action Plan/Resolution | E6: Owner | F6: Importance | G6: Date Entered | H6: Date to Review | I6: Date Resolved
A7: 1 | B7: What is the issue? | C7: How will this impact scope, schedule & cost? | D7: How do you intend to deal with this issue? | E7: Who manages this issue?
A8: 2
A9: 3
A10: 4
A11: 5
A12: 6
A13: 7
A14: 8
A15: 9
A16: 10
A17: 11
A18: 12
A19: 13
... A21: 15
I24: © Global Knowledge Training LLC

Sheet Action
A1: Action Items
A2: Project | C2: =Data!B1 | F2: Project # | G2: =Data!B2
A3: Project manager | C3: =Data!B3 | F3: Sponsor | G3: =Data!B4
A4: Project artifacts | C4: =Data!B5 | F4: Updated | G4: =Data!B6
A6: ID | B6: Action Item | C6: Owner | D6: Status | E6: Date Entered | F6: Planned Completion | G6: Actual Completion | H6: Comments
A7: 1 | B7: Define project scope and deliverables | C7: Mohammedreda El aroui | D7: Completed | E7: 2026-01-15 | F7: 2026-01-20 | G7: 2026-01-20 | H7: Approved by sponsor
A8: 2 | B8: Set up development environment | C8: Dev Lead | D8: Completed | E8: 2026-01-20 | F8: 2026-01-25 | G8: 2026-01-24
A9: 3 | B9: Research scanning libraries and tools | C9: Dev Lead | D9: Completed | E9: 2026-01-25 | F9: 2026-02-01 | G9: 2026-02-01 | H9: Selected nmap, bandit, zxcvbn
A10: 4 | B10: Develop port scanning module | C10: Dev Team | D10: In Progress | E10: 2026-02-01 | F10: 2026-02-20
A11: 5 | B11: Develop password strength evaluator | C11: Dev Team | D11: In Progress | E11: 2026-02-01 | F11: 2026-02-20
A12: 6 | B12: Design risk scoring algorithm | C12: Dev Lead | D12: Not Started | E12: 2026-02-10 | F12: 2026-02-28
A13: 7 | B13: Create dashboard/report UI | C13: Dev Team | D13: Not Started | E13: 2026-02-15 | F13: 2026-03-15
A14: 8 | B14: Conduct internal QA testing | C14: QA Team | D14: Not Started | E14: 2026-03-15 | F14: 2026-03-30
A15: 9 | B15: Conduct beta user testing | C15: QA Team | D15: Not Started | E15: 2026-04-01 | F15: 2026-04-15
A16: 10 | B16: Legal/privacy compliance review | C16: Data Privacy Officer | D16: Not Started | E16: 2026-03-01 | F16: 2026-03-20
A17: 11
A18: 12
A19: 13
A20: 14
A21: 15
H24: © Global Knowledge Training LLC

Sheet Miles
A1: Deliverable Milestones
A2: Project | C2: =Data!B1 | F2: Project # | G2: =Data!B2
A3: Project manager | C3: =Data!B3 | F3: Sponsor | G3: =Data!B4
A4: Project artifacts | C4: =Data!B5 | F4: Updated | G4: =Data!B6
A6: ID | B6: Milestone | C6: Description | D6: Planned Completion | E6: Actual Completion | F6: Objectives | G6: Assumptions | H6: Constraints
A7: 1 | B7: Project Kickoff | C7: Official start; team assembled and charter signed | D7: 2026-01-10 | E7: 2026-01-10 | F7: Launch project with full team and sponsor approval | G7: Funding approved before kickoff | H7: Team must be available from day 1
A8: 2 | B8: Requirements Finalized | C8: All functional and technical requirements documented and approved | D8: 2026-01-28 | E8: 2026-01-28 | F8: Clear scope baseline established | G8: Stakeholders available for interviews | H8: No scope changes after this milestone
A9: 3 | B9: Architecture Design Complete | C9: System design and tech stack approved | D9: 2026-02-05 | E9: 2026-02-05 | F9: Technical blueprint ready for development | G9: Dev tools and libraries selected | H9: Must support Windows, Linux, macOS
A10: 4 | B10: Core Scanning Modules Developed | C10: Port scanner, password evaluator, config checker complete | D10: 2026-03-10 | F10: All primary scan features functional | G10: Dev environment stable | H10: Must pass internal unit tests
A11: 5 | B11: Risk Scoring & Dashboard Complete | C11: Risk algorithm and UI dashboard finalized | D11: 2026-04-01 | F11: Full product functionality achieved | G11: Core modules tested and approved | H11: UX review required
A12: 6 | B12: QA Testing Complete | C12: All internal and beta testing cycles finished | D12: 2026-04-30 | F12: Product meets quality standards | G12: Beta users available for testing | H12: All critical bugs resolved
A13: 7 | B13: Project Closure | C13: Final delivery, documentation, sponsor sign-off | D13: 2026-05-07 | F13: Successful handover to stakeholders | G13: All deliverables accepted | H13: Final report approved by sponsor
A14: 8
A15: 9
A16: 10
A17: 11
A18: 12
A19: 13
A20: 14
A21: 15
H24: © Global Knowledge Training LLC

Sheet WBS
A1: Work Breakdown Structure
A2: Project | C2: =Data!B1 | G2: Project # | H2: =Data!B2
A3: Project manager | C3: =Data!B3 | G3: Sponsor | H3: =Data!B4
A4: Project artifacts | C4: =Data!B5 | G4: Updated | H4: =Data!B6
A6: ID | B6: Task | C6: Dependencies | D6: Status | E6: Effort Hours | F6: Cost | G6: Start Date | H6: Planned Completion | I6: Estimate to Completion | J6: Actual Completion | K6: Resource
A7: 1 | B7: Project Initiation | D7: Completed | E7: 16 | F7: 0 | G7: 2026-01-10 | H7: 2026-01-20 | J7: 2026-01-20 | K7: Mohammedreda El aroui
A8: 2 | B8: Define scope and objectives | C8: 1 | D8: Completed | E8: 8 | F8: 0 | G8: 2026-01-10 | H8: 2026-01-15 | J8: 2026-01-15 | K8: Mohammedreda El aroui
A9: 3 | B9: Stakeholder identification | C9: 1 | D9: Completed | E9: 4 | F9: 0 | G9: 2026-01-12 | H9: 2026-01-16 | J9: 2026-01-16 | K9: Mohammedreda El aroui
A10: 4 | B10: Project planning and scheduling | C10: 2,3 | D10: Completed | E10: 12 | F10: 0 | G10: 2026-01-15 | H10: 2026-01-22 | J10: 2026-01-22 | K10: Mohammedreda El aroui
A11: 5 | B11: Requirements gathering | C11: 4 | D11: Completed | E11: 20 | F11: 0 | G11: 2026-01-18 | H11: 2026-01-28 | J11: 2026-01-28 | K11: Dev Lead
A12: 6 | B12: System architecture design | C12: 5 | D12: Completed | E12: 16 | F12: 0 | G12: 2026-01-25 | H12: 2026-02-05 | J12: 2026-02-05 | K12: Dev Lead
A13: 7 | B13: Set up development environment | C13: 6 | D13: Completed | E13: 8 | F13: 0 | G13: 2026-02-01 | H13: 2026-02-07 | J13: 2026-02-07 | K13: Dev Team
A14: 8 | B14: Develop port scanning module | C14: 7 | D14: In Progress | E14: 30 | F14: 0 | G14: 2026-02-08 | H14: 2026-02-20 | I14: 2026-02-20 | K14: Dev Team
A15: 9 | B15: Develop password strength evaluator | C15: 7 | D15: In Progress | E15: 20 | F15: 0 | G15: 2026-02-08 | H15: 2026-02-20 | I15: 2026-02-20 | K15: Dev Team
A16: 10 | B16: Develop vulnerability/config checker | C16: 8,9 | D16: Not Started | E16: 40 | F16: 0 | G16: 2026-02-20 | H16: 2026-03-10 | I16: 2026-03-10 | K16: Dev Team
A17: 11 | B17: Develop risk scoring algorithm | C17: 10 | D17: Not Started | E17: 24 | F17: 0 | G17: 2026-03-01 | H17: 2026-03-15 | I17: 2026-03-15 | K17: Dev Lead
A18: 12 | B18: Build dashboard/report UI | C18: 11 | D18: Not Started | E18: 40 | F18: 0 | G18: 2026-03-10 | H18: 2026-04-01 | I18: 2026-04-01 | K18: Dev Team
A19: 13 | B19: Internal QA testing | C19: 12 | D19: Not Started | E19: 20 | F19: 0 | G19: 2026-04-01 | H19: 2026-04-15 | I19: 2026-04-15 | K19: QA Team
A20: 14 | B20: Beta user testing | C20: 13 | D20: Not Started | E20: 16 | F20: 0 | G20: 2026-04-15 | H20: 2026-04-30 | I20: 2026-04-30 | K20: QA Team
A21: 15 | B21: Project closure and documentation | C21: 14 | D21: Not Started | E21: 12 | F21: 0 | G21: 2026-04-30 | H21: 2026-05-07 | I21: 2026-05-07 | K21: Mohammedreda El aroui
K24: © Global Knowledge Training LLC

Sheet Roster
A1: Roster
A2: Project | B2: =Data!B1 | F2: Project # | G2: =Data!B2
A3: Project manager | B3: =Data!B3 | F3: Sponsor | G3: =Data!B4
A4: Project artifacts | B4: =Data!B5 | F4: Updated | G4: =Data!B6
A6: Name | B6: Core/ Extended Team | C6: Title | D6: Dept. | E6: Phone | F6: Cell Phone | G6: E-Mail | H6: Project Role
E7: 000.000.0000 | F7: 000.000.0000
H36: © Global Knowledge Training LLC

Sheet R&R
A1: Roles and Responsibilities
A2: Project | B2: =Data!B1 | F2: Project # | G2: =Data!B2
A3: Project manager | B3: =Data!B3 | F3: Sponsor | G3: =Data!B4
A4: Project artifacts | B4: =Data!B5 | F4: Updated | G4: =Data!B6
A6: Name | B6: Core/ Extended Team | C6: % Assigned | D6: Deliverables Leading | E6: Deliverables Participating On | F6: Project Role | G6: Responsibility | H6: Other Project Assignments
H24: © Global Knowledge Training LLC

Sheet RAM
A1: Resource Assignment Matrix
A2: Project | D2: =Data!B1 | H2: Project # | K2: =Data!B2
A3: Project manager | D3: =Data!B3 | H3: Sponsor | K3: =Data!B4
A4: Project artifacts | D4: =Data!B5 | H4: Updated | K4: =Data!B6
A6: Project Task
B7: Project Management and Requirements
C9: Initiation
A10: 1
A11: 2
A12: 3
A13: 4
A14: 5
C16: Planning
A17: 1
A18: 2
A19: 3
A20: 4
A21: 5
A22: 6
A23: 7
A24: 8
A25: 9
A26: 10
A27: 11
A28: 12
... A39: 23
C41: Execution
A42: 1
A43: 2
A44: 3
A45: 4
A46: 5
A47: 6
C49: Closing
A50: 1
A51: 2
A52: 3
A53: 4
A54: 5
A55: 6
...

Sheet RCM
A1: Resource Commitment Matrix
A2: Project | B2: =Data!B1 | G2: Project # | I2: =Data!B2
A3: Project manager | B3: =Data!B3 | G3: Sponsor | I3: =Data!B4
A4: Project artifacts | B4: =Data!B5 | G4: Updated | I4: =Data!B6
B6: Effort Hours Committed
A7: Names | B7: Jan | C7: Feb | D7: Mar | E7: Apr | F7: May | G7: June | H7: July | I7: Aug | J7: Sept | K7: Oct | L7: Nov | M7: Dec | N7: Total
N8: =SUM(B8:M8)
N9: =SUM(B9:M9)
N10: =SUM(B10:M10)
N11: =SUM(B11:M11)
N12: =SUM(B12:M12)
N13: =SUM(B13:M13)
N14: =SUM(B14:M14)
N15: =SUM(B15:M15)
N16: =SUM(B16:M16)
N17: =SUM(B17:M17)
N18: =SUM(B18:M18)
N19: =SUM(B19:M19)
... N36: =SUM(B36:M36)
A37: Total | B37: =SUM(B8:B36) | C37: =SUM(C8:C36) | D37: =SUM(D8:D36) | E37: =SUM(E8:E36) | F37: =SUM(F8:F36) | G37: =SUM(G8:G36) | H37: =SUM(H8:H36) | I37: =SUM(I8:I36) | ... M37: =SUM(M8:M36) | N37: =SUM(B37:M37)
N39: © Global Knowledge Training LLC

Sheet A&C
A1: Assumptions and Constraints
A2: Project | C2: =Data!B1 | D2: Project # | E2: =Data!B2
A3: Project manager | C3: =Data!B3 | D3: Sponsor | E3: =Data!B4
A4: Project artifacts | C4: =Data!B5 | D4: Updated | E4: =Data!B6
A6: ID | B6: Description | C6: Comments | D6: Type | E6: Status | F6: Date Entered
A7: 1 | B7: The scanner will run on Windows, Linux, and macOS systems | D7: Assumption | E7: Active | F7: 2/4/2026
A8: 2 | B8: Users will have basic internet access to receive updates | D8: Assumption | E8: Active | F8: 2/4/2026
A9: 3 | B9: Open-source libraries (nmap, bandit, zxcvbn) will be used to reduce costs | D9: Assumption | E9: Active | F9: 2/4/2026
A10: 4 | B10: The project budget is fixed and approved by the sponsor | D10: Constraint | E10: Active | F10: 2/4/2026
A11: 5 | B11: Project must be completed by May 7, 2026 | D11: Constraint | E11: Active | F11: 2/4/2026
A12: 6 | B12: All user data collected must comply with GDPR | D12: Constraint | E12: Active | F12: 2/4/2026
A13: 7 | B13: Scanner must be able to run offline (no internet required during scan) | D13: Assumption | E13: Active | F13: 2/4/2026
A14: 8 | B14: Team has necessary technical skills in Python and network security | D14: Assumption | E14: Active | F14: 2/4/2026
A15: 9 | B15: Third-party threat intelligence APIs will remain available throughout | D15: Assumption | E15: Active | F15: 2/4/2026
A16: 10 | B16: v1 will be a desktop/CLI tool, not a cloud service | D16: Constraint | E16: Active | F16: 2/4/2026
A17: 11
A18: 12
A19: 13
A20: 14
A21: 15
F24: © Global Knowledge Training LLC

Sheet Decision
A1: Decision Log
A2: Project | C2: =Data!B1 | D2: Project # | E2: =Data!B2
A3: Project manager | C3: =Data!B3 | D3: Sponsor | E3: =Data!B4
A4: Project artifacts | C4: =Data!B5 | D4: Updated | E4: =Data!B6
A6: ID | B6: Decision Description | C6: Comments | D6: Owner | E6: Status | F6: Date Entered
A7: 1
A8: 2
A9: 3
A10: 4
A11: 5
A12: 6
A13: 7
A14: 8
A15: 9
A16: 10
A17: 11
A18: 12
... A21: 15
F24: © Global Knowledge Training LLC

Sheet Comm
A1: Communication Plan
A2: Project | C2: =Data!B1 | D2: Project # | E2: =Data!B2
A3: Project manager | C3: =Data!B3 | D3: Sponsor | E3: =Data!B4
A4: Project artifacts | C4: =Data!B5 | D4: Updated | E4: =Data!B6
A6: ID | B6: Communication | C6: Description | D6: Frequency | E6: Format | F6: Owner | G6: Recipient/ Attendees
A7: 1 | B7: Weekly Status Meeting | C7: Review sprint progress, blockers, and action items | D7: Weekly | E7: Video call / Meeting notes | F7: Mohammedreda El aroui | G7: All team members
A8: 2 | B8: Sponsor Update Report | C8: High-level project status, budget, risks for sponsor | D8: Bi-weekly | E8: Email report | F8: Mohammedreda El aroui | G8: Mohamed AAZI
A9: 3 | B9: Sprint Review | C9: Demo of completed features to stakeholders | D9: End of each sprint | E9: Live demo / Presentation | F9: Dev Lead | G9: Sponsor, PM, QA
A10: 4 | B10: Risk Review | C10: Review and update risk register | D10: Monthly | E10: Risk register document | F10: Mohammedreda El aroui | G10: All team members
A11: 5 | B11: Change Request Notification | C11: Notify stakeholders of scope/schedule change requests | D11: As needed | E11: Email + Change log | F11: Mohammedreda El aroui | G11: Sponsor, Dev Lead
A12: 6 | B12: Project Kickoff Meeting | C12: Introduce project goals, team, plan, and timeline | D12: Once (project start) | E12: In-person / Video call | F12: Mohammedreda El aroui | G12: All stakeholders
A13: 7 | B13: User Testing Report | C13: Share findings from beta user testing sessions | D13: End of testing phase | E13: Written report + Dashboard | F13: QA Lead | G13: PM, Sponsor
A14: 8 | B14: Project Closure Report | C14: Document final deliverables, lessons learned, sign-off | D14: Project end | E14: Final report document | F14: Mohammedreda El aroui | G14: Mohamed AAZI, All team
A15: 9
A16: 10
A17: 11
A18: 12
A19: 13
A20: 14
A21: 15
A22: 16
A23: 17
G25: © Global Knowledge Training LLC

Sheet Stake
A1: Stakeholder Analysis
A2: Project | C2: =Data!B1 | D2: Project # | E2: =Data!B2
A3: Project Manager | C3: =Data!B3 | D3: Sponsor | E3: =Data!B4
A4: Project Artifacts | C4: =Data!B5 | D4: Updated | E4: =Data!B6
A6: ID | B6: Stakeholder | C6: Role | D6: Impact | E6: Influence | F6: Risk Tolerance | G6: Needs | H6: Responsibility
A7: 1 | B7: Mohamed AAZI | C7: Project Sponsor | D7: High | E7: High | F7: Low | G7: On-time delivery, budget compliance | H7: Approve budget and scope changes
A8: 2 | B8: Mohammedreda El aroui | C8: Project Manager | D8: High | E8: High | F8: Medium | G8: Clear requirements and team support | H8: Plan, execute, monitor project
A9: 3 | B9: Development Team | C9: Technical Developers | D9: High | E9: Medium | F9: Medium | G9: Clear specs, tools, and environment | H9: Build and test the scanner
A10: 4 | B10: End Users (Individuals/SMEs) | C10: Primary Users | D10: High | E10: Low | F10: Medium | G10: Simple, accurate, actionable tool | H10: Use tool and provide feedback
A11: 5 | B11: Data Privacy Officer | C11: Compliance Advisor | D11: Medium | E11: High | F11: Low | G11: GDPR compliance, data minimization | H11: Review data handling procedures
A12: 6 | B12: QA/Testing Team | C12: Quality Assurance | D12: Medium | E12: Medium | F12: Medium | G12: Test cases and requirements docs | H12: Test and validate scanner output
A13: 7
A14: 8
A15: 9
A16: 10
A17: 11
A18: 12
A19: 13
A20: 14
A21: 15
H24: © Global Knowledge Training LLC

Sheet Expectations
A1: Expectations
A2: Project | B2: =Data!B1 | C2: Project # | E2: =Data!B2
A3: Project manager | B3: =Data!B3 | C3: Sponsor | E3: =Data!B4
A4: Project artifacts | B4: =Data!B5 | C4: Updated | E4: =Data!B6
A6: ID | B6: Expectation Description | C6: Source | D6: Must Have | E6: Want to Have | F6: Nice to Have | G6: Date Identified
G39: © Global Knowledge Training LLC

Sheet Chg Log
A1: Change Control Log
A2: Project | C2: =Data!B1 | G2: Project # | H2: =Data!B2
A3: Project Manager | C3: =Data!B3 | G3: Sponsor | H3: =Data!B4
A4: Project Artifacts | C4: =Data!B5 | G4: Updated | H4: =Data!B6
A6: ID | B6: Change Description | C6: Priority | D6: Originator | E6: Date Entered | F6: Date Assigned | G6: Evaluator | H6: Status | I6: Date of Decision | J6: Included in Rev. #
A7: 1
A8: 2
A9: 3
A10: 4
A11: 5
A12: 6
A13: 7
A14: 8
A15: 9
A16: 10
A17: 11
A18: 12
... A21: 15
J24: © Global Knowledge Training LLC

Sheet Deliver
A1: Deliverable Acceptance Log
A2: Project | C2: =Data!B1 | D2: Project # | E2: =Data!B2
A3: Project manager | C3: =Data!B3 | D3: Sponsor | E3: =Data!B4
A4: Project artifacts | C4: =Data!B5 | D4: Updated | E4: =Data!B6
A6: ID | B6: Deliverable Description | C6: Comments | D6: Evaluator | E6: Status | F6: Date of Decision
A7: 1
A8: 2
A9: 3
A10: 4
A11: 5
A12: 6
A13: 7
A14: 8
A15: 9
A16: 10
A17: 11
A18: 12
... A21: 15
F24: © Global Knowledge Training LLC

Sheet PERT
A1: PERT Analysis
A2: Project | C2: =Data!B1 | I2: Project # | K2: =Data!B2
A3: Project Manager | C3: =Data!B3 | I3: Sponsor | K3: =Data!B4
A4: Project Artifacts | C4: =Data!B5 | I4: Updated | K4: =Data!B6
A6: ID | B6: Task | C6: Most Likely | D6: Min | E6: Max | F6: PERT Est | G6: 15/15 Comp'ed Est | H6: Std Dev | I6: +1 Std Dev | J6: -1 Std Dev | K6: +2 Std Dev | L6: -2 Std Dev | M6: +3 Std Dev | N6: -3 Std Dev
F7: =(D7+E7+(4*C7))/6 | G7: =F7/0.72 | H7: =(E7-D7)/6 | I7: =$G7+$H7 | J7: =$G7-$H7 | K7: =$G7+(2*$H7) | L7: =$G7-(2*$H7) | M7: =$G7+(3*$H7) | N7: =$G7-(3*$H7)
F8: =(D8+E8+(4*C8))/6 | G8: =F8/0.72 | H8: =(E8-D8)/6 | I8: =$G8+$H8 | J8: =$G8-$H8 | K8: =$G8+(2*$H8) | L8: =$G8-(2*$H8) | M8: =$G8+(3*$H8) | N8: =$G8-(3*$H8)
F9: =(D9+E9+(4*C9))/6 | G9: =F9/0.72 | H9: =(E9-D9)/6 | I9: =$G9+$H9 | J9: =$G9-$H9 | K9: =$G9+(2*$H9) | L9: =$G9-(2*$H9) | M9: =$G9+(3*$H9) | N9: =$G9-(3*$H9)
F10: =(D10+E10+(4*C10))/6 | G10: =F10/0.72 | H10: =(E10-D10)/6 | I10: =$G10+$H10 | J10: =$G10-$H10 | K10: =$G10+(2*$H10) | L10: =$G10-(2*$H10) | M10: =$G10+(3*$H10) | N10: =$G10-(3*$H10)
F11: =(D11+E11+(4*C11))/6 | G11: =F11/0.72 | H11: =(E11-D11)/6 | I11: =$G11+$H11 | J11: =$G11-$H11 | K11: =$G11+(2*$H11) | L11: =$G11-(2*$H11) | M11: =$G11+(3*$H11) | N11: =$G11-(3*$H11)
F12: =(D12+E12+(4*C12))/6 | G12: =F12/0.72 | H12: =(E12-D12)/6 | I12: =$G12+$H12 | J12: =$G12-$H12 | K12: =$G12+(2*$H12) | L12: =$G12-(2*$H12) | M12: =$G12+(3*$H12) | N12: =$G12-(3*$H12)
F13: =(D13+E13+(4*C13))/6 | G13: =F13/0.72 | H13: =(E13-D13)/6 | I13: =$G13+$H13 | J13: =$G13-$H13 | K13: =$G13+(2*$H13) | L13: =$G13-(2*$H13) | M13: =$G13+(3*$H13) | N13: =$G13-(3*$H13)
F14: =(D14+E14+(4*C14))/6 | G14: =F14/0.72 | H14: =(E14-D14)/6 | I14: =$G14+$H14 | J14: =$G14-$H14 | K14: =$G14+(2*$H14) | L14: =$G14-(2*$H14) | M14: =$G14+(3*$H14) | N14: =$G14-(3*$H14)
F15: =(D15+E15+(4*C15))/6 | G15: =F15/0.72 | H15: =(E15-D15)/6 | I15: =$G15+$H15 | J15: =$G15-$H15 | K15: =$G15+(2*$H15) | L15: =$G15-(2*$H15) | M15: =$G15+(3*$H15) | N15: =$G15-(3*$H15)
F16: =(D16+E16+(4*C16))/6 | G16: =F16/0.72 | H16: =(E16-D16)/6 | I16: =$G16+$H16 | J16: =$G16-$H16 | K16: =$G16+(2*$H16) | L16: =$G16-(2*$H16) | M16: =$G16+(3*$H16) | N16: =$G16-(3*$H16)
F17: =(D17+E17+(4*C17))/6 | G17: =F17/0.72 | H17: =(E17-D17)/6 | I17: =$G17+$H17 | J17: =$G17-$H17 | K17: =$G17+(2*$H17) | L17: =$G17-(2*$H17) | M17: =$G17+(3*$H17) | N17: =$G17-(3*$H17)
F18: =(D18+E18+(4*C18))/6 | G18: =F18/0.72 | H18: =(E18-D18)/6 | I18: =$G18+$H18 | J18: =$G18-$H18 | K18: =$G18+(2*$H18) | L18: =$G18-(2*$H18) | M18: =$G18+(3*$H18) | N18: =$G18-(3*$H18)
... F69: =(D69+E69+(4*C69))/6 | G69: =F69/0.72 | H69: =(E69-D69)/6 | I69: =$G69+$H69 | J69: =$G69-$H69 | K69: =$G69+(2*$H69) | L69: =$G69-(2*$H69) | M69: =$G69+(3*$H69) | N69: =$G69-(3*$H69)
N71: © Global Knowledge Training LLC

Sheet Delphi
A1: Delphi Exercise
A2: Project | B2: =Data!B1 | G2: Project # | I2: =Data!B2
A3: Project manager | B3: =Data!B3 | G3: Sponsor | I3: =Data!B4
A4: Project artifacts | B4: =Data!B5 | G4: Updated | I4: =Data!B6
A6: Task | B6: Sample task here
A7: Team members | B7: Name 1 | C7: Name 2 | D7: Name 3 | E7: Name 4 | F7: Name 5 | G7: Name 6 | H7: Name 7 | I7: Name 8 | J7: Total | K7: Average
A8: Most likely | J8: =SUM(B8:I8) | K8: =AVERAGE(B8:I8)
A9: Minimum | J9: =SUM(B9:I9) | K9: =AVERAGE(B9:I9)
A10: Maximum | J10: =SUM(B10:I10) | K10: =AVERAGE(B10:I10)
A12: Task | B12: Sample task here
A13: Team members | B13: Name 1 | C13: Name 2 | D13: Name 3 | E13: Name 4 | F13: Name 5 | G13: Name 6 | H13: Name 7 | I13: Name 8 | J13: Total | K13: Average
A14: Most likely | J14: =SUM(B14:I14) | K14: =AVERAGE(B14:I14)
A15: Minimum | J15: =SUM(B15:I15) | K15: =AVERAGE(B15:I15)
A16: Maximum | J16: =SUM(B16:I16) | K16: =AVERAGE(B16:I16)
A18: Task | B18: Sample task here
A19: Team members | B19: Name 1 | C19: Name 2 | D19: Name 3 | E19: Name 4 | F19: Name 5 | G19: Name 6 | H19: Name 7 | I19: Name 8 | J19: Total | K19: Average
A20: Most likely | J20: =SUM(B20:I20) | K20: =AVERAGE(B20:I20)
A21: Minimum | J21: =SUM(B21:I21) | K21: =AVERAGE(B21:I21)
A22: Maximum | J22: =SUM(B22:I22) | K22: =AVERAGE(B22:I22)
A24: Task | B24: Sample task here
A25: Team members | B25: Name 1 | C25: Name 2 | D25: Name 3 | E25: Name 4 | F25: Name 5 | G25: Name 6 | H25: Name 7 | I25: Name 8 | J25: Total | K25: Average
A26: Most likely | J26: =SUM(B26:I26) | K26: =AVERAGE(B26:I26)
A27: Minimum | J27: =SUM(B27:I27) | K27: =AVERAGE(B27:I27)
A28: Maximum | J28: =SUM(B28:I28) | K28: =AVERAGE(B28:I28)
A30: Task | B30: Sample task here
A31: Team members | B31: Name 1 | C31: Name 2 | D31: Name 3 | E31: Name 4 | F31: Name 5 | G31: Name 6 | H31: Name 7 | I31: Name 8 | J31: Total | K31: Average
A32: Most likely | J32: =SUM(B32:I32) | K32: =AVERAGE(B32:I32)
A33: Minimum | J33: =SUM(B33:I33) | K33: =AVERAGE(B33:I33)
A34: Maximum | J34: =SUM(B34:I34) | K34: =AVERAGE(B34:I34)
A36: Task | B36: Sample task here
A37: Team members | B37: Name 1 | C37: Name 2 | D37: Name 3 | E37: Name 4 | F37: Name 5 | G37: Name 6 | H37: Name 7 | I37: Name 8 | J37: Total | K37: Average
A38: Most likely | J38: =SUM(B38:I38) | K38: =AVERAGE(B38:I38)
A39: Minimum | J39: =SUM(B39:I39) | K39: =AVERAGE(B39:I39)
A40: Maximum | J40: =SUM(B40:I40) | K40: =AVERAGE(B40:I40)
A42: Task | B42: Sample task here
A43: Team members | B43: Name 1 | C43: Name 2 | D43: Name 3 | E43: Name 4 | F43: Name 5 | G43: Name 6 | H43: Name 7 | I43: Name 8 | J43: Total | K43: Average
A44: Most likely | J44: =SUM(B44:I44) | K44: =AVERAGE(B44:I44)
A45: Minimum | J45: =SUM(B45:I45) | K45: =AVERAGE(B45:I45)
A46: Maximum | J46: =SUM(B46:I46) | K46: =AVERAGE(B46:I46)
A48: Task | B48: Sample task here
...

Sheet TimeSum
A1: Timesheet Totals
A2: Project | B2: =Data!B1 | G2: Project # | I2: =Data!B2
A3: Project manager | B3: =Data!B3 | G3: Sponsor | I3: =Data!B4
A4: Project artifacts | B4: =Data!B5 | G4: Updated | I4: =Data!B6
B6: Effort Hours Spent
A7: Name | B7: Jan | C7: Feb | D7: Mar | E7: Apr | F7: May | G7: June | H7: July | I7: Aug | J7: Sept | K7: Oct | L7: Nov | M7: Dec | N7: Total
N8: =SUM(B8:M8)
N9: =SUM(B9:M9)
N10: =SUM(B10:M10)
N11: =SUM(B11:M11)
N12: =SUM(B12:M12)
N13: =SUM(B13:M13)
N14: =SUM(B14:M14)
N15: =SUM(B15:M15)
N16: =SUM(B16:M16)
N17: =SUM(B17:M17)
N18: =SUM(B18:M18)
N19: =SUM(B19:M19)
... N36: =SUM(B36:M36)
A37: Total | B37: =SUM(B8:B36) | C37: =SUM(C8:C36) | D37: =SUM(D8:D36) | E37: =SUM(E8:E36) | F37: =SUM(F8:F36) | G37: =SUM(G8:G36) | H37: =SUM(H8:H36) | I37: =SUM(I8:I36) | ... M37: =SUM(M8:M36) | N37: =SUM(B37:M37)
N39: © Global Knowledge Training LLC

Sheet Timesheet
A1: Timesheet
A2: Project | B2: =Data!B1 | G2: Project # | I2: =Data!B2
A3: Project manager | B3: =Data!B3 | G3: Sponsor | I3: =Data!B4
A4: Project artifacts | B4: =Data!B5 | G4: Updated | I4: =Data!B6
A6: Name | B6: Insert name here
B7: Effort Hours Spent
A8: Task | B8: Jan | C8: Feb | D8: Mar | E8: Apr | F8: May | G8: June | H8: July | I8: Aug | J8: Sept | K8: Oct | L8: Nov | M8: Dec | N8: Total
N9: =SUM(B9:M9)
N10: =SUM(B10:M10)
N11: =SUM(B11:M11)
N12: =SUM(B12:M12)
N13: =SUM(B13:M13)
N14: =SUM(B14:M14)
N15: =SUM(B15:M15)
N16: =SUM(B16:M16)
N17: =SUM(B17:M17)
N18: =SUM(B18:M18)
N19: =SUM(B19:M19)
N20: =SUM(B20:M20)
... N37: =SUM(B37:M37)
A38: Total | B38: =SUM(B9:B37) | C38: =SUM(C9:C37) | D38: =SUM(D9:D37) | E38: =SUM(E9:E37) | F38: =SUM(F9:F37) | G38: =SUM(G9:G37) | H38: =SUM(H9:H37) | I38: =SUM(I9:I37) | ... M38: =SUM(M9:M37) | N38: =SUM(B38:M38)
N40: © Global Knowledge Training LLC

Sheet Size Est
A1: Initial Project Size Estimate
A2: Project | C2: =Data!B1 | D2: Project # | E2: =Data!B2
A3: Project manager | C3: =Data!B3 | D3: Sponsor | E3: =Data!B4
A4: Project artifacts | C4: =Data!B5 | D4: Updated | E4: =Data!B6
C6: Scope Estimate
C7: Technology Systems Impacted
C8: 1 to 2 | D8: 3 to 5 | E8: 6 or more
A9: # of Business Requirements | B9: Less than 50 | C9: Automatically do; no approval needed
B10: 51 - 100
B11: 100 or more | E11: Approval required
C13: Cost Estimate
C14: # of Resources Involved
C15: Less than 10 | D15: 11 to 50 | E15: 51 or More
A16: # of Business Requirements | B16: Less than 50 | C16: Automatically do; no approval needed
B17: 51 - 100
B18: 100 or more | E18: Approval required
C20: Cost Estimate
C21: # of Resources Involved
C22: Less than 10 | D22: 11 to 50 | E22: 51 or More
A23: Benefit | B23: Low | E23: Avoid
B24: Medium
B25: High | C25: Automatically do; no approval needed
E27: © Global Knowledge Training LLC

Sheet Res Load
A1: Resource Loading
A2: Project | B2: Project title here | D2: Project # | E2: Project # here
A3: Project manager | B3: Project manager name here | D3: Sponsor | E3: Sponsor name here
A4: Project artifacts | B4: Location of project documents here | D4: Updated | E4: Date of update here
A5: Team Member:
A6: Effort Hours Committed
A7: ID | B7: Task | C7: Effort Hours | D7: Duration (Weeks) | E7: Available Hours | F7: Commitment Level
F8: =IF(C8<E8,C8/D8,E8/D8)
F9: =IF(C9<E9,C9/D9,E9/D9)
F10: =IF(C10<E10,C10/D10,E10/D10)
F11: =IF(C11<E11,C11/D11,E11/D11)
F12: =IF(C12<E12,C12/D12,E12/D12)
F13: =IF(C13<E13,C13/D13,E13/D13)
F14: =IF(C14<E14,C14/D14,E14/D14)
F15: =IF(C15<E15,C15/D15,E15/D15)
F16: =IF(C16<E16,C16/D16,E16/D16)
F17: =IF(C17<E17,C17/D17,E17/D17)
F18: =IF(C18<E18,C18/D18,E18/D18)
F19: =IF(C19<E19,C19/D19,E19/D19)
... F36: =IF(C36<E36,C36/D36,E36/D36)
B37: Total | C37: =SUM(C8:C36) | D37: =SUM(D8:D36) | E37: =SUM(E8:E36) | F37: =IF(C37<E37,C37/D37,E37/D37)
F39: © Global Knowledge Training LLC

Sheet Qual Metrics
A1: Project Quality Metrics
A2: Project | B2: =Data!B1 | D2: Project # | E2: =Data!B2
A3: Project Manager | B3: =Data!B3 | D3: Sponsor | E3: =Data!B4
A4: Project Artifacts | B4: =Data!B5 | D4: Updated | E4: =Data!B6
A6: ID | B6: Critical Success Criteria | C6: Potential Quality Metric | E6: Priority | F6: Metric Target | G6: Action Plan
G32: © Global Knowledge Training LLC

Sheet Project Register
A1: Project Register
A2: Project | C2: =Data!B1 | E2: Project # | F2: =Data!B2
A3: Project manager | C3: =Data!B3 | E3: Sponsor | F3: =Data!B4
A4: Project artifacts | C4: =Data!B5 | E4: Updated | F4: =Data!B6
G6: Order of Magnitude
A7: ID | B7: Project Name | C7: Description | D7: Category | E7: Executive Champion | F7: Goal/Strategy Alignment | G7: Time | H7: Costs | I7: Return | J7: Status | K7: Rank
A8: 1
A9: 2
A10: 3
A11: 4
A12: 5
A13: 6
A14: 7
A15: 8
A16: 9
A17: 10
A18: 11
A19: 12
... A22: 15

Sheet Portfolio Review
A1: Periodic Portfolio Review Report
A2: Project | C2: =Data!B1 | E2: Project # | F2: =Data!B2
A3: Project manager | C3: =Data!B3 | E3: Sponsor | F3: =Data!B4
A4: Project artifacts | C4: =Data!B5 | E4: Updated | F4: =Data!B6
E6: Analysis | G6: Status
A7: ID | B7: Project Name | C7: Description | D7: Rank | E7: Costs (CPI) | F7: Schedule (SPI) | G7: Time | H7: Costs | I7: Scope | J7: Return | K7: Recommendation
A8: 1
A9: 2
A10: 3
A11: 4
A12: 5
A13: 6
A14: 7
A15: 8
A16: Periodic Portfolio Review Report
A17: Project | C17: =(C2) | E17: Project # | F17: =(F2)
A18: Project manager | C18: =(C3) | E18: Sponsor | F18: =(F3)
A19: Project artifacts | C19: =(C4) | E19: Updated | F19: =(F4)
E21: Analysis | G21: Status
A22: ID | B22: Project Name | C22: Description | D22: Rank | E22: Costs (CPI) | F22: Schedule (SPI) | G22: Time | H22: Costs | I22: Scope | J22: Return | K22: Recommendation
A23: 9
A24: 10
A25: 11
A26: 12
A27: 13
A28: 14
A29: 15
